Workbook
Name Slicer_Clean_Category: #N/A
Name Slicer_Clean_Category2: #N/A
Name Slicer_Clean_Region: #N/A
Name Slicer_Clean_Region1: #N/A

Sheet Sales_Performance_Analysis.csv
A1: Order ID | B1: Order Date | C1: Region | D1: Product Category | E1: Sales Amount | F1: Quantity Sold | G1: Discount (%) | H1: Profit | I1: Order ID | J1: Order Date | K1: Clean Region | L1: Clean Category | M1: Sales Amount | N1: Regional Avg Sales | O1: Quantity Sold | P1: Discount (%) | Q1: Profit | S1: Region | T1: Regional Avg Sales | U1: Using TRIM | X1: Using UPPER | AA1: Using LOWER
A2: ab899d2f | B2: 45022 | C2: norTh | D2: groceries | E2: 859.29 | F2: 44 | G2: 37 | H2: 1653.87 | I2: ab899d2f | J2: 45022 | K2: {=_xlfn.IFS(LEFT(C2:C4001,1)="N","North",LEFT(C2:C4001,1)="E","East",LEFT(C2:C4001,1)="M","East",LEFT(C2:C4001,1)="W","West",LEFT(C2:C4001,1)="S","South")} -> North | L2: {=_xlfn.IFS(LEFT(D2:D4001,1)="G","Groceries",LEFT(D2:D4001,1)="C","Clothing",LEFT(D2:D4001,1)="F","Furniture",LEFT(D2:D4001,1)="S","Sports",LEFT(D2:D4001,1)="E","Electronics")} -> Groceries | M2: 859.29 | N2: =VLOOKUP($K2,Sales_Performance_Analysis.csv!$S$1:$T$5,2,FALSE) -> 2573.1196 | O2: 44 | P2: 37 | Q2: 1653.87 | S2: North | T2: =AVERAGEIF(Sales_Performance_Analysis.csv!K:K,"north",Sales_Performance_Analysis.csv!E:E) -> 2573.1196 | U2: {=TRIM(_xlfn.ANCHORARRAY(K2))} -> North | V2: {=TRIM(_xlfn.ANCHORARRAY(L2))} -> Groceries | X2: {=UPPER(_xlfn.ANCHORARRAY(K2))} -> NORTH | Y2: {=UPPER(_xlfn.ANCHORARRAY(L2))} -> GROCERIES | AA2: {=LOWER(_xlfn.ANCHORARRAY(X2))} -> north | AB2: {=LOWER(_xlfn.ANCHORARRAY(Y2))} -> groceries
A3: 73484eb1 | B3: 45412 | C3: Messt | D3: groceries | E3: 1546.81 | F3: 23 | G3: 33 | H3: 1932.71 | I3: 73484eb1 | J3: 45412 | K3: East | L3: Groceries | M3: 1546.81 | N3: =VLOOKUP($K3,Sales_Performance_Analysis.csv!$S$1:$T$5,2,FALSE) -> 2529.8487 | O3: 23 | P3: 33 | Q3: 1932.71 | S3: East | T3: =AVERAGEIF(Sales_Performance_Analysis.csv!K:K,"east",Sales_Performance_Analysis.csv!E:E) -> 2529.8487 | U3: East | V3: Groceries | X3: EAST | Y3: GROCERIES | AA3: east | AB3: groceries
A4: 19395924 | B4: 45363 | C4: eAsT | D4: groceries | E4: 4703.58 | F4: 31 | G4: 15 | H4: 527.47 | I4: 19395924 | J4: 45363 | K4: East | L4: Groceries | M4: 4703.58 | N4: =VLOOKUP($K4,Sales_Performance_Analysis.csv!$S$1:$T$5,2,FALSE) -> 2529.8487 | O4: 31 | P4: 15 | Q4: 527.47 | S4: West | T4: =AVERAGEIF(Sales_Performance_Analysis.csv!K:K,"west",Sales_Performance_Analysis.csv!E:E) -> 2536.311 | U4: East | V4: Groceries | X4: EAST | Y4: GROCERIES | AA4: east | AB4: groceries
A5: b3fded3d | B5: 45331 | C5: eAsT | D5: groceries | E5: 3377.17 | F5: 47 | G5: 3 | H5: 482.65 | I5: b3fded3d | J5: 45331 | K5: East | L5: Groceries | M5: 3377.17 | N5: =VLOOKUP($K5,Sales_Performance_Analysis.csv!$S$1:$T$5,2,FALSE) -> 2529.8487 | O5: 47 | P5: 3 | Q5: 482.65 | S5: South | T5: =AVERAGEIF(Sales_Performance_Analysis.csv!K:K,"south",Sales_Performance_Analysis.csv!E:E) -> 2478.5568 | U5: East | V5: Groceries | X5: EAST | Y5: GROCERIES | AA5: east | AB5: groceries
A6: 6e4bdd51 | B6: 45502 | C6: s0uTH | D6: Clothing | E6: 3517.49 | F6: 6 | G6: 28 | H6: 748.72 | I6: 6e4bdd51 | J6: 45502 | K6: South | L6: Clothing | M6: 3517.49 | N6: =VLOOKUP($K6,Sales_Performance_Analysis.csv!$S$1:$T$5,2,FALSE) -> 2478.5568 | O6: 6 | P6: 28 | Q6: 748.72 | U6: South | V6: Clothing | X6: SOUTH | Y6: CLOTHING | AA6: south | AB6: clothing
A7: 21d88d69 | B7: 45164 | C7: eAsT | D7: FURNiture | E7: 362.55 | F7: 19 | G7: 50 | H7: 314.71 | I7: 21d88d69 | J7: 45164 | K7: East | L7: Furniture | M7: 362.55 | N7: =VLOOKUP($K7,Sales_Performance_Analysis.csv!$S$1:$T$5,2,FALSE) -> 2529.8487 | O7: 19 | P7: 50 | Q7: 314.71 | U7: East | V7: Furniture | X7: EAST | Y7: FURNITURE | AA7: east | AB7: furniture
A8: 9da2704d | B8: 45572 | C8: eAsT | D8: sports | E8: 4811.17 | F8: 22 | G8: 18 | H8: 1372.89 | I8: 9da2704d | J8: 45572 | K8: East | L8: Sports | M8: 4811.17 | N8: =VLOOKUP($K8,Sales_Performance_Analysis.csv!$S$1:$T$5,2,FALSE) -> 2529.8487 | O8: 22 | P8: 18 | Q8: 1372.89 | U8: East | V8: Sports | X8: EAST | Y8: SPORTS | AA8: east | AB8: sports
A9: a1bd6815 | B9: 45000 | C9: Messt | D9: electronicS | E9: 3565.2 | F9: 22 | G9: 16 | H9: 1437.3 | I9: a1bd6815 | J9: 45000 | K9: East | L9: Electronics | M9: 3565.2 | N9: =VLOOKUP($K9,Sales_Performance_Analysis.csv!$S$1:$T$5,2,FALSE) -> 2529.8487 | O9: 22 | P9: 16 | Q9: 1437.3 | U9: East | V9: Electronics | X9: EAST | Y9: ELECTRONICS | AA9: east | AB9: electronics
A10: 0bbd51fc | B10: 45106 | C10: eAsT | D10: Clothing | E10: 3805.25 | F10: 19 | G10: 3 | H10: 1537.28 | I10: 0bbd51fc | J10: 45106 | K10: East | L10: Clothing | M10: 3805.25 | N10: =VLOOKUP($K10,Sales_Performance_Analysis.csv!$S$1:$T$5,2,FALSE) -> 2529.8487 | O10: 19 | P10: 3 | Q10: 1537.28 | U10: East | V10: Clothing | X10: EAST | Y10: CLOTHING | AA10: east | AB10: clothing
A11: 8bf7e4b3 | B11: 44998 | C11: s0uTH | D11: Clothing | E11: 2178.72 | F11: 15 | G11: 24 | H11: 1696.65 | I11: 8bf7e4b3 | J11: 44998 | K11: South | L11: Clothing | M11: 2178.72 | N11: =VLOOKUP($K11,Sales_Performance_Analysis.csv!$S$1:$T$5,2,FALSE) -> 2478.5568 | O11: 15 | P11: 24 | Q11: 1696.65 | U11: South | V11: Clothing | X11: SOUTH | Y11: CLOTHING | AA11: south | AB11: clothing
A12: e6cf1255 | B12: 45439 | C12: Messt | D12: groceries | E12: 2844.93 | F12: 34 | G12: 12 | H12: 1166.39 | I12: e6cf1255 | J12: 45439 | K12: East | L12: Groceries | M12: 2844.93 | N12: =VLOOKUP($K12,Sales_Performance_Analysis.csv!$S$1:$T$5,2,FALSE) -> 2529.8487 | O12: 34 | P12: 12 | Q12: 1166.39 | U12: East | V12: Groceries | X12: EAST | Y12: GROCERIES | AA12: east | AB12: groceries
A13: 3ba1fc5c | B13: 45291 | C13: Messt | D13: electronicS | E13: 3600.04 | F13: 10 | G13: 2 | H13: 1632.75 | I13: 3ba1fc5c | J13: 45291 | K13: East | L13: Electronics | M13: 3600.04 | N13: =VLOOKUP($K13,Sales_Performance_Analysis.csv!$S$1:$T$5,2,FALSE) -> 2529.8487 | O13: 10 | P13: 2 | Q13: 1632.75 | U13: East | V13: Electronics | X13: EAST | Y13: ELECTRONICS | AA13: east | AB13: electronics
A14: 388ff70d | B14: 45239 | C14: eAsT | D14: sports | E14: 941.88 | F14: 13 | G14: 28 | H14: 646.49 | I14: 388ff70d | J14: 45239 | K14: East | L14: Sports | M14: 941.88 | N14: =VLOOKUP($K14,Sales_Performance_Analysis.csv!$S$1:$T$5,2,FALSE) -> 2529.8487 | O14: 13 | P14: 28 | Q14: 646.49 | U14: East | V14: Sports | X14: EAST | Y14: SPORTS | AA14: east | AB14: sports
A15: ce2e9002 | B15: 44919 | C15: s0uTH | D15: sports | E15: 3300.86 | F15: 1 | G15: 48 | H15: 86.9 | I15: ce2e9002 | J15: 44919 | K15: South | L15: Sports | M15: 3300.86 | N15: =VLOOKUP($K15,Sales_Performance_Analysis.csv!$S$1:$T$5,2,FALSE) -> 2478.5568 | O15: 1 | P15: 48 | Q15: 86.9 | U15: South | V15: Sports | X15: SOUTH | Y15: SPORTS | AA15: south | AB15: sports
A16: a4f9a338 | B16: 45329 | C16: eAsT | D16: groceries | E16: 1081.62 | F16: 4 | G16: 19 | H16: 611.06 | I16: a4f9a338 | J16: 45329 | K16: East | L16: Groceries | M16: 1081.62 | N16: =VLOOKUP($K16,Sales_Performance_Analysis.csv!$S$1:$T$5,2,FALSE) -> 2529.8487 | O16: 4 | P16: 19 | Q16: 611.06 | U16: East | V16: Groceries | X16: EAST | Y16: GROCERIES | AA16: east | AB16: groceries
A17: eadceaa8 | B17: 45318 | C17: eAsT | D17: FURNiture | E17: 3455.67 | F17: 39 | G17: 21 | H17: 208.1 | I17: eadceaa8 | J17: 45318 | K17: East | L17: Furniture | M17: 3455.67 | N17: =VLOOKUP($K17,Sales_Performance_Analysis.csv!$S$1:$T$5,2,FALSE) -> 2529.8487 | O17: 39 | P17: 21 | Q17: 208.1 | U17: East | V17: Furniture | X17: EAST | Y17: FURNITURE | AA17: east | AB17: furniture
... A19: 35358e9c | B19: 45471 | C19: norTh | D19: Clothing | E19: 2784.79 | F19: 35 | G19: 40 | H19: 999.6 | I19: 35358e9c | J19: 45471 | K19: North | L19: Clothing | M19: 2784.79 | N19: =VLOOKUP($K19,Sales_Performance_Analysis.csv!$S$1:$T$5,2,FALSE) -> 2573.1196 | O19: 35 | P19: 40 | Q19: 999.6 | U19: North | V19: Clothing | X19: NORTH | Y19: CLOTHING | AA19: north | AB19: clothing
A20: 31676338 | B20: 45246 | C20: s0uTH | D20: Clothing | E20: 1082.98 | F20: 8 | G20: 11 | H20: 1604.19 | I20: 31676338 | J20: 45246 | K20: South | L20: Clothing | M20: 1082.98 | N20: =VLOOKUP($K20,Sales_Performance_Analysis.csv!$S$1:$T$5,2,FALSE) -> 2478.5568 | O20: 8 | P20: 11 | Q20: 1604.19 | U20: South | V20: Clothing | X20: SOUTH | Y20: CLOTHING | AA20: south | AB20: clothing
A21: 05d72e20 | B21: 45556 | C21: eAsT | D21: Clothing | E21: 787.79 | F21: 47 | G21: 18 | H21: 1313.33 | I21: 05d72e20 | J21: 45556 | K21: East | L21: Clothing | M21: 787.79 | N21: =VLOOKUP($K21,Sales_Performance_Analysis.csv!$S$1:$T$5,2,FALSE) -> 2529.8487 | O21: 47 | P21: 18 | Q21: 1313.33 | U21: East | V21: Clothing | X21: EAST | Y21: CLOTHING | AA21: east | AB21: clothing
A22: 68dbe328 | B22: 45566 | C22: s0uTH | D22: FURNiture | E22: 312.7 | F22: 36 | G22: 43 | H22: 559.52 | I22: 68dbe328 | J22: 45566 | K22: South | L22: Furniture | M22: 312.7 | N22: =VLOOKUP($K22,Sales_Performance_Analysis.csv!$S$1:$T$5,2,FALSE) -> 2478.5568 | O22: 36 | P22: 43 | Q22: 559.52 | U22: South | V22: Furniture | X22: SOUTH | Y22: FURNITURE | AA22: south | AB22: furniture
A23: 78d3f47b | B23: 45077 | C23: eAsT | D23: sports | E23: 265.32 | F23: 21 | G23: 36 | H23: 595.91 | I23: 78d3f47b | J23: 45077 | K23: East | L23: Sports | M23: 265.32 | N23: =VLOOKUP($K23,Sales_Performance_Analysis.csv!$S$1:$T$5,2,FALSE) -> 2529.8487 | O23: 21 | P23: 36 | Q23: 595.91 | U23: East | V23: Sports | X23: EAST | Y23: SPORTS | AA23: east | AB23: sports
A24: 9e4d1fe0 | B24: 45400 | C24: Messt | D24: FURNiture | E24: 1253.64 | F24: 35 | G24: 14 | H24: 1653.66 | I24: 9e4d1fe0 | J24: 45400 | K24: East | L24: Furniture | M24: 1253.64 | N24: =VLOOKUP($K24,Sales_Performance_Analysis.csv!$S$1:$T$5,2,FALSE) -> 2529.8487 | O24: 35 | P24: 14 | Q24: 1653.66 | U24: East | V24: Furniture | X24: EAST | Y24: FURNITURE | AA24: east | AB24: furniture
A25: 9215a70e | B25: 45341 | C25: Messt | D25: Clothing | E25: 1874.07 | F25: 28 | G25: 23 | H25: 1783.26 | I25: 9215a70e | J25: 45341 | K25: East | L25: Clothing | M25: 1874.07 | N25: =VLOOKUP($K25,Sales_Performance_Analysis.csv!$S$1:$T$5,2,FALSE) -> 2529.8487 | O25: 28 | P25: 23 | Q25: 1783.26 | U25: East | V25: Clothing | X25: EAST | Y25: CLOTHING | AA25: east | AB25: clothing
A26: 54ca3433 | B26: 45041 | C26: eAsT | D26: Clothing | E26: 2561.71 | F26: 44 | G26: 10 | H26: 800.82 | I26: 54ca3433 | J26: 45041 | K26: East | L26: Clothing | M26: 2561.71 | N26: =VLOOKUP($K26,Sales_Performance_Analysis.csv!$S$1:$T$5,2,FALSE) -> 2529.8487 | O26: 44 | P26: 10 | Q26: 800.82 | U26: East | V26: Clothing | X26: EAST | Y26: CLOTHING | AA26: east | AB26: clothing
A27: 0ba75cc7 | B27: 45059 | C27: Messt | D27: sports | E27: 1960.74 | F27: 50 | G27: 6 | H27: 1530.61 | I27: 0ba75cc7 | J27: 45059 | K27: East | L27: Sports | M27: 1960.74 | N27: =VLOOKUP($K27,Sales_Performance_Analysis.csv!$S$1:$T$5,2,FALSE) -> 2529.8487 | O27: 50 | P27: 6 | Q27: 1530.61 | U27: East | V27: Sports | X27: EAST | Y27: SPORTS | AA27: east | AB27: sports
A28: 601860b1 | B28: 45037 | C28: eAsT | D28: electronicS | E28: 2415.44 | F28: 35 | G28: 14 | H28: 335.57 | I28: 601860b1 | J28: 45037 | K28: East | L28: Electronics | M28: 2415.44 | N28: =VLOOKUP($K28,Sales_Performance_Analysis.csv!$S$1:$T$5,2,FALSE) -> 2529.8487 | O28: 35 | P28: 14 | Q28: 335.57 | U28: East | V28: Electronics | X28: EAST | Y28: ELECTRONICS | AA28: east | AB28: electronics
A29: e393e106 | B29: 45290 | C29: eAsT | D29: electronicS | E29: 2284.22 | F29: 8 | G29: 41 | H29: 1866.59 | I29: e393e106 | J29: 45290 | K29: East | L29: Electronics | M29: 2284.22 | N29: =VLOOKUP($K29,Sales_Performance_Analysis.csv!$S$1:$T$5,2,FALSE) -> 2529.8487 | O29: 8 | P29: 41 | Q29: 1866.59 | U29: East | V29: Electronics | X29: EAST | Y29: ELECTRONICS | AA29: east | AB29: electronics
A30: 7ab3d472 | B30: 44885 | C30: Messt | D30: sports | E30: 2118.55 | F30: 29 | G30: 24 | H30: 702.15 | I30: 7ab3d472 | J30: 44885 | K30: East | L30: Sports | M30: 2118.55 | N30: =VLOOKUP($K30,Sales_Performance_Analysis.csv!$S$1:$T$5,2,FALSE) -> 2529.8487 | O30: 29 | P30: 24 | Q30: 702.15 | U30: East | V30: Sports | X30: EAST | Y30: SPORTS | AA30: east | AB30: sports
A31: 01d9b1ae | B31: 45248 | C31: s0uTH | D31: groceries | E31: 4803.6 | F31: 11 | G31: 12 | H31: 1086.74 | I31: 01d9b1ae | J31: 45248 | K31: South | L31: Groceries | M31: 4803.6 | N31: =VLOOKUP($K31,Sales_Performance_Analysis.csv!$S$1:$T$5,2,FALSE) -> 2478.5568 | O31: 11 | P31: 12 | Q31: 1086.74 | U31: South | V31: Groceries | X31: SOUTH | Y31: GROCERIES | AA31: south | AB31: groceries
A32: 20385cb6 | B32: 45533 | C32: norTh | D32: groceries | E32: 4297 | F32: 17 | G32: 49 | H32: 678.7 | I32: 20385cb6 | J32: 45533 | K32: North | L32: Groceries | M32: 4297 | N32: =VLOOKUP($K32,Sales_Performance_Analysis.csv!$S$1:$T$5,2,FALSE) -> 2573.1196 | O32: 17 | P32: 49 | Q32: 678.7 | U32: North | V32: Groceries | X32: NORTH | Y32: GROCERIES | AA32: north | AB32: groceries
... A69: 92458ed3 | B69: 45024 | C69: norTh | D69: FURNiture | E69: 1356.62 | F69: 2 | G69: 21 | H69: 1213.34 | I69: 92458ed3 | J69: 45024 | K69: North | L69: Furniture | M69: 1356.62 | N69: =VLOOKUP($K69,Sales_Performance_Analysis.csv!$S$1:$T$5,2,FALSE) -> 2573.1196 | O69: 2 | P69: 21 | Q69: 1213.34 | U69: North | V69: Furniture | X69: NORTH | Y69: FURNITURE | AA69: north | AB69: furniture
A70: 76740552 | B70: 45201 | C70: s0uTH | D70: electronicS | E70: 2905.8 | F70: 20 | G70: 10 | H70: 1417.43 | I70: 76740552 | J70: 45201 | K70: South | L70: Electronics | M70: 2905.8 | N70: =VLOOKUP($K70,Sales_Performance_Analysis.csv!$S$1:$T$5,2,FALSE) -> 2478.5568 | O70: 20 | P70: 10 | Q70: 1417.43 | U70: South | V70: Electronics | X70: SOUTH | Y70: ELECTRONICS | AA70: south | AB70: electronics
A71: f92de80d | B71: 45060 | C71: s0uTH | D71: FURNiture | E71: 2065.42 | F71: 22 | G71: 15 | H71: 787.51 | I71: f92de80d | J71: 45060 | K71: South | L71: Furniture | M71: 2065.42 | N71: =VLOOKUP($K71,Sales_Performance_Analysis.csv!$S$1:$T$5,2,FALSE) -> 2478.5568 | O71: 22 | P71: 15 | Q71: 787.51 | U71: South | V71: Furniture | X71: SOUTH | Y71: FURNITURE | AA71: south | AB71: furniture
A72: 647ff51a | B72: 45094 | C72: eAsT | D72: Clothing | E72: 272.88 | F72: 47 | G72: 29 | H72: 1208.68 | I72: 647ff51a | J72: 45094 | K72: East | L72: Clothing | M72: 272.88 | N72: =VLOOKUP($K72,Sales_Performance_Analysis.csv!$S$1:$T$5,2,FALSE) -> 2529.8487 | O72: 47 | P72: 29 | Q72: 1208.68 | U72: East | V72: Clothing | X72: EAST | Y72: CLOTHING | AA72: east | AB72: clothing
A73: f8548ec7 | B73: 45594 | C73: eAsT | D73: Clothing | E73: 4126.4 | F73: 34 | G73: 13 | H73: 1690.11 | I73: f8548ec7 | J73: 45594 | K73: East | L73: Clothing | M73: 4126.4 | N73: =VLOOKUP($K73,Sales_Performance_Analysis.csv!$S$1:$T$5,2,FALSE) -> 2529.8487 | O73: 34 | P73: 13 | Q73: 1690.11 | U73: East | V73: Clothing | X73: EAST | Y73: CLOTHING | AA73: east | AB73: clothing
A74: 7855a0d2 | B74: 45195 | C74: norTh | D74: FURNiture | E74: 4204.55 | F74: 49 | G74: 1 | H74: 1534.82 | I74: 7855a0d2 | J74: 45195 | K74: North | L74: Furniture | M74: 4204.55 | N74: =VLOOKUP($K74,Sales_Performance_Analysis.csv!$S$1:$T$5,2,FALSE) -> 2573.1196 | O74: 49 | P74: 1 | Q74: 1534.82 | U74: North | V74: Furniture | X74: NORTH | Y74: FURNITURE | AA74: north | AB74: furniture
A75: bf586512 | B75: 45226 | C75: Messt | D75: Clothing | E75: 2130.98 | F75: 7 | G75: 29 | H75: 679.16 | I75: bf586512 | J75: 45226 | K75: East | L75: Clothing | M75: 2130.98 | N75: =VLOOKUP($K75,Sales_Performance_Analysis.csv!$S$1:$T$5,2,FALSE) -> 2529.8487 | O75: 7 | P75: 29 | Q75: 679.16 | U75: East | V75: Clothing | X75: EAST | Y75: CLOTHING | AA75: east | AB75: clothing
A76: deea1965 | B76: 45436 | C76: s0uTH | D76: FURNiture | E76: 1253.28 | F76: 4 | G76: 48 | H76: 317.33 | I76: deea1965 | J76: 45436 | K76: South | L76: Furniture | M76: 1253.28 | N76: =VLOOKUP($K76,Sales_Performance_Analysis.csv!$S$1:$T$5,2,FALSE) -> 2478.5568 | O76: 4 | P76: 48 | Q76: 317.33 | U76: South | V76: Furniture | X76: SOUTH | Y76: FURNITURE | AA76: south | AB76: furniture
A77: a0a8290f | B77: 45478 | C77: s0uTH | D77: sports | E77: 1050.29 | F77: 30 | G77: 4 | H77: 423.5 | I77: a0a8290f | J77: 45478 | K77: South | L77: Sports | M77: 1050.29 | N77: =VLOOKUP($K77,Sales_Performance_Analysis.csv!$S$1:$T$5,2,FALSE) -> 2478.5568 | O77: 30 | P77: 4 | Q77: 423.5 | U77: South | V77: Sports | X77: SOUTH | Y77: SPORTS | AA77: south | AB77: sports
...

Sheet Task 1
A1: Order Date | B1: Clean Region | C1: Clean Category
A2: 45022 | B2: {=_xlfn.IFS(LEFT(Sales_Performance_Analysis.csv!C2:C4001,1)="N","North",LEFT(Sales_Performance_Analysis.csv!C2:C4001,1)="E","East",LEFT(Sales_Performance_Analysis.csv!C2:C4001,1)="M","East",LEFT(Sales_Performance_Analysis.csv!C2:C4001,1)="W","West",LEFT(Sales_Performance_Analysis.csv!C2:C4001,1)="S","South")} -> North | C2: {=_xlfn.IFS(LEFT(Sales_Performance_Analysis.csv!D2:D4001,1)="G","Groceries",LEFT(Sales_Performance_Analysis.csv!D2:D4001,1)="C","Clothing",LEFT(Sales_Performance_Analysis.csv!D2:D4001,1)="F","Furniture",LEFT(Sales_Performance_Analysis.csv!D2:D4001,1)="S","Sports",LEFT(Sales_Performance_Analysis.csv!D2:D4001,1)="E","Electronics")} -> Groceries
A3: 45412 | B3: East | C3: Groceries
A4: 45363 | B4: East | C4: Groceries
A5: 45331 | B5: East | C5: Groceries
A6: 45502 | B6: South | C6: Clothing
A7: 45164 | B7: East | C7: Furniture
A8: 45572 | B8: East | C8: Sports
A9: 45000 | B9: East | C9: Electronics
A10: 45106 | B10: East | C10: Clothing
A11: 44998 | B11: South | C11: Clothing
A12: 45439 | B12: East | C12: Groceries
A13: 45291 | B13: East | C13: Electronics
A14: 45239 | B14: East | C14: Sports
... A4001: 45465 | B4001: East | C4001: Furniture

Sheet Task 4
A1: Total sales for each Region | D1: Category | E1: Avg Dis % | F1: Avg Profit
A2: Region | B2: Sum of Sales | D2: Furniture | E2: =AVERAGEIF(Sales_Performance_Analysis.csv!L:L,"furniture",Sales_Performance_Analysis.csv!P:P) -> 25.230392 | F2: =AVERAGEIF(Sales_Performance_Analysis.csv!L:L,"Furniture",Sales_Performance_Analysis.csv!Q:Q) -> 1023.3827
A3: North | B3: =SUMIF(Sales_Performance_Analysis.csv!$K:$K,Sales_Performance_Analysis.csv!$S2,Sales_Performance_Analysis.csv!$M:$M) -> 2539669
A4: East | B4: =SUMIF(Sales_Performance_Analysis.csv!$K:$K,Sales_Performance_Analysis.csv!$S3,Sales_Performance_Analysis.csv!$M:$M) -> 2623453.1
A5: West | B5: =SUMIF(Sales_Performance_Analysis.csv!$K:$K,Sales_Performance_Analysis.csv!$S4,Sales_Performance_Analysis.csv!$M:$M) -> 2153328
A6: South | B6: =SUMIF(Sales_Performance_Analysis.csv!$K:$K,Sales_Performance_Analysis.csv!$S5,Sales_Performance_Analysis.csv!$M:$M) -> 2793333.5

Sheet Task 5
A1: Clean Category | B1: Clean Region | C1: Sum of Sales Amount | D1: Sum of Profit
A2: Clothing | C2: 2156007.6 | D2: 856347.49
B3: East | C3: 544147.05 | D3: 206173.43
B4: North | C4: 575975.88 | D4: 207145.82
B5: South | C5: 607267.41 | D5: 257012.1
B6: West | C6: 428617.24 | D6: 186016.14
A7: Electronics | C7: 2047834.9 | D7: 803657.96
B8: East | C8: 487335.04 | D8: 196771.53
B9: North | C9: 527159.55 | D9: 203772.53
B10: South | C10: 542960.29 | D10: 218587.48
B11: West | C11: 490380.05 | D11: 184526.42
A12: Furniture | C12: 2049496.2 | D12: 835080.32
B13: East | C13: 568091.34 | D13: 229622.02
B14: North | C14: 494993.63 | D14: 209391.78
B15: South | C15: 542353.65 | D15: 214936.91
B16: West | C16: 444057.54 | D16: 181129.61
A17: Groceries | C17: 1864225.1 | D17: 739605.38
B18: East | C18: 442386.15 | D18: 179081.18
B19: North | C19: 471913.51 | D19: 172529.97
B20: South | C20: 552437.15 | D20: 236904.15
B21: West | C21: 397488.25 | D21: 151090.08
A22: Sports | C22: 1992220 | D22: 797005.36
B23: East | C23: 581493.55 | D23: 223349.19
B24: North | C24: 469626.43 | D24: 177465.97
B25: South | C25: 548315.02 | D25: 228538.76
B26: West | C26: 392784.96 | D26: 167651.44
A27: Grand Total | C27: 10109784 | D27: 4031696.5

Sheet Bar Chart
A3: Clean Region | B3: Sum of Sales Amount
A4: East | B4: 2623453.1
A5: North | B5: 2539669
A6: South | B6: 2793333.5
A7: Grand Total | B7: 7956455.7

Sheet Pie Chart
A3: Clean Category | B3: Sum of Sales Amount
A4: Clothing | B4: 1727390.3
A5: Electronics | B5: 1557454.9
A6: Furniture | B6: 1605438.6
A7: Groceries | B7: 1466736.8
A8: Sports | B8: 1599435
A9: Grand Total | B9: 7956455.6

Sheet Stacked Bar Chart
A1: Sum of Sales Amount | B1: Clean Category
A2: Clean Region | B2: Clothing | C2: Electronics | D2: Furniture | E2: Groceries | F2: Sports | G2: Grand Total
A3: East | B3: 544147.05 | C3: 487335.04 | D3: 568091.34 | E3: 442386.15 | F3: 581493.55 | G3: 2623453.1
A4: North | B4: 575975.88 | C4: 527159.55 | D4: 494993.63 | E4: 471913.51 | F4: 469626.43 | G4: 2539669
A5: South | B5: 607267.41 | C5: 542960.29 | D5: 542353.65 | E5: 552437.15 | F5: 548315.02 | G5: 2793333.5
A6: Grand Total | B6: 1727390.3 | C6: 1557454.9 | D6: 1605438.6 | E6: 1466736.8 | F6: 1599435 | G6: 7956455.6

Sheet Dashboards
IC10: Sales Performance Dashboard
KK57: =SUM(Sales_Performance_Analysis.csv!O2:O4001) -> 102791 | NY57: =SUM(Sales_Performance_Analysis.csv!Q2:Q4001) -> 4031696.5
GS58: =SUM(Sales_Performance_Analysis.csv!M2:M4001) -> 10109784

Sheet Task 10
A1: Sales Amount | B1: Profit | C1: Profit Margin%
A2: 859.29 | B2: 1653.87 | C2: {=(B2:B4001/A2:A4001)*100} -> 192.46936
A3: 1546.81 | B3: 1932.71 | C3: 124.94812
A4: 4703.58 | B4: 527.47 | C4: 11.214224
A5: 3377.17 | B5: 482.65 | C5: 14.291552
A6: 3517.49 | B6: 748.72 | C6: 21.285633
A7: 362.55 | B7: 314.71 | C7: 86.804579
A8: 4811.17 | B8: 1372.89 | C8: 28.535471
A9: 3565.2 | B9: 1437.3 | C9: 40.314709
A10: 3805.25 | B10: 1537.28 | C10: 40.398923
A11: 2178.72 | B11: 1696.65 | C11: 77.873706
A12: 2844.93 | B12: 1166.39 | C12: 40.9989
A13: 3600.04 | B13: 1632.75 | C13: 45.353663
A14: 941.88 | B14: 646.49 | C14: 68.638255
... A4001: 2975.86 | B4001: 1870.61 | C4001: 62.859476
